{"name": "test_login[user0]", "status": "broken", "statusDetails": {"message": "TypeError: 'module' object is not callable", "trace": "@pytest.fixture(scope=\"function\")\n    def driver():\n        config = LocalConfig()  # instancia\n        opts = UiAutomator2Options()\n        opts.platform_name = config.PLATFORM_NAME\n        opts.automation_name = config.AUTOMATION_NAME\n        opts.device_name = config.DEVICE_NAME\n        opts.platform_version = config.PLATFORM_VERSION\n        opts.app = config.APP_PATH\n        opts.app_package = config.APP_PACKAGE\n        opts.app_activity = config.APP_ACTIVITY\n        opts.no_reset = config.NO_RESET\n        opts.auto_grant_permissions = config.AUTO_GRANT_PERMISSIONS\n        opts.new_command_timeout = config.NEW_COMMAND_TIMEOUT\n    \n        command_executor = f\"http://{config.APPIUM_HOST}:{config.APPIUM_PORT}/wd/hub\"\n    \n>       driver_instance = webdriver(command_executor=command_executor, options=opts)\n                          ^^^^^^^^^^^^^^^^^^^^^^^^^^^^^^^^^^^^^^^^^^^^^^^^^^^^^^^^^^\nE       TypeError: 'module' object is not callable\n\nconftest.py:35: TypeError"}, "parameters": [{"name": "user", "value": "{'email': 'derly+qa02@vitawallet.io', 'password': 'vitawallet'}"}], "start": 1759482158608, "stop": 1759482158608, "uuid": "28be6d10-ea65-45e3-89f7-32b696e3a27f", "historyId": "cb43fbe24d4c7dde0fd229d0182b8b9e", "testCaseId": "851f638a1293a2d1aa1b69497a224bb7", "fullName": "tests.test_sample#test_login", "labels": [{"name": "parentSuite", "value": "tests"}, {"name": "suite", "value": "test_sample"}, {"name": "host", "value": "DESKTOP-USD8UUS"}, {"name": "thread", "value": "13476-MainThread"}, {"name": "framework", "value": "pytest"}, {"name": "language", "value": "cpython3"}, {"name": "package", "value": "tests.test_sample"}], "titlePath": ["tests", "test_sample.py"]}